Workbook

Sheet activos
A2: MATRIZ | C2: ESPECIFICA | E2: SUB ESPECIFICA | G2: PUBLICACION 21 | I2: TERCER DIGITO DE PUB 21 Y | K2: SUB ESPECIFICA DE PUB 21 | M2: CUENTA MATRIZ | O2: AUXILIAR DE PUB 21
A3: cod | B3: DENOMINACION | C3: cod | D3: DENOMINACION | E3: cod | F3: DENOMINACION | G3: cod | H3: DENOMINACION | I3: cod | J3: DENOMINACION | K3: cod | L3: DENOMINACION | M3: CODIGO UNIFICADO | N3: DENOMINACION DE LA CUENTA | O3: cod | P3: DENOMINACION | Q3: CODIGO UNIFICADO | R3: DENOMINACION DE LA CUENTA | S3: =CONCATENATE(TEXT(LEFT(G3,2),"00"),"-",TEXT(RIGHT(G3,1),"0")) -> co-d
A4: 1 | B4: =VLOOKUP(A4,'ACTIVOS CODIGO'!A:B,2,0) -> ACTIVO | G4: 0 | M4: =CONCATENATE(TEXT(A4,"0"),"-",TEXT(C4,"0"),"-",TEXT(E4,"0"),"-",TEXT(LEFT(G4,2),"00"),"-",TEXT(RIGHT(G4,1),"0"),TEXT(I4,"0"),"-",TEXT(K4,"00")) -> 1-0-0-00-00-00 | N4: =IF(L4="",IF(J4="",IF(H4="",IF(F4="",IF(D4="",B4,D4),F4),H4),J4),L4) -> ACTIVO | O4: =IF(P4="",0,IF(M3=M4,IF(O3="",0,O3)+1,"")) -> 0 | Q4: =CONCATENATE(TEXT(A4,"0"),"-",TEXT(C4,"0"),"-",TEXT(E4,"0"),"-",TEXT(LEFT(G4,2),"00"),"-",TEXT(RIGHT(G4,1),"0"),TEXT(I4,"0"),"-",TEXT(K4,"00"),"-",TEXT(O4,"000")) -> 1-0-0-00-00-00-000 | R4: =IF(P4="",IF(L4="",IF(J4="",IF(H4="",IF(F4="",IF(D4="",B4,D4),F4),H4),J4),L4),P4) -> ACTIVO | S4: =CONCATENATE(TEXT(LEFT(G4,2),"00"),"-",TEXT(RIGHT(G4,1),"0")) -> 00-0
A5: 1 | B5: =VLOOKUP(A5,'ACTIVOS CODIGO'!A:B,2,0) -> ACTIVO | C5: 1 | D5: =VLOOKUP(C5,'ACTIVOS CODIGO'!C:D,2,0) -> ACTIVO DEL TESORO = ACTIVO CORRIENTE | G5: 0 | M5: =CONCATENATE(TEXT(A5,"0"),"-",TEXT(C5,"0"),"-",TEXT(E5,"0"),"-",TEXT(LEFT(G5,2),"00"),"-",TEXT(RIGHT(G5,1),"0"),TEXT(I5,"0"),"-",TEXT(K5,"00")) -> 1-1-0-00-00-00 | N5: =IF(L5="",IF(J5="",IF(H5="",IF(F5="",IF(D5="",B5,D5),F5),H5),J5),L5) -> ACTIVO DEL TESORO = ACTIVO CORRIENTE | O5: =IF(P5="",0,IF(M4=M5,IF(O4="",0,O4)+1,"")) -> 0 | Q5: =CONCATENATE(TEXT(A5,"0"),"-",TEXT(C5,"0"),"-",TEXT(E5,"0"),"-",TEXT(LEFT(G5,2),"00"),"-",TEXT(RIGHT(G5,1),"0"),TEXT(I5,"0"),"-",TEXT(K5,"00"),"-",TEXT(O5,"000")) -> 1-1-0-00-00-00-000 | R5: =IF(P5="",IF(L5="",IF(J5="",IF(H5="",IF(F5="",IF(D5="",B5,D5),F5),H5),J5),L5),P5) -> ACTIVO DEL TESORO = ACTIVO CORRIENTE | S5: =CONCATENATE(TEXT(LEFT(G5,2),"00"),"-",TEXT(RIGHT(G5,1),"0")) -> 00-0 | T5: ACTIVO CORRIENTE | U5: 100
A6: 1 | B6: =VLOOKUP(A6,'ACTIVOS CODIGO'!A:B,2,0) -> ACTIVO | C6: 1 | D6: =VLOOKUP(C6,'ACTIVOS CODIGO'!C:D,2,0) -> ACTIVO DEL TESORO = ACTIVO CORRIENTE | E6: 1 | F6: =VLOOKUP(E6,'ACTIVOS CODIGO'!E:F,2,0) -> ACTIVO DISPONIBLE | G6: 0 | M6: =CONCATENATE(TEXT(A6,"0"),"-",TEXT(C6,"0"),"-",TEXT(E6,"0"),"-",TEXT(LEFT(G6,2),"00"),"-",TEXT(RIGHT(G6,1),"0"),TEXT(I6,"0"),"-",TEXT(K6,"00")) -> 1-1-1-00-00-00 | N6: =IF(L6="",IF(J6="",IF(H6="",IF(F6="",IF(D6="",B6,D6),F6),H6),J6),L6) -> ACTIVO DISPONIBLE | O6: =IF(P6="",0,IF(M5=M6,IF(O5="",0,O5)+1,"")) -> 0 | Q6: =CONCATENATE(TEXT(A6,"0"),"-",TEXT(C6,"0"),"-",TEXT(E6,"0"),"-",TEXT(LEFT(G6,2),"00"),"-",TEXT(RIGHT(G6,1),"0"),TEXT(I6,"0"),"-",TEXT(K6,"00"),"-",TEXT(O6,"000")) -> 1-1-1-00-00-00-000 | R6: =IF(P6="",IF(L6="",IF(J6="",IF(H6="",IF(F6="",IF(D6="",B6,D6),F6),H6),J6),L6),P6) -> ACTIVO DISPONIBLE | S6: =CONCATENATE(TEXT(LEFT(G6,2),"00"),"-",TEXT(RIGHT(G6,1),"0")) -> 00-0
A7: 1 | B7: =VLOOKUP(A7,'ACTIVOS CODIGO'!A:B,2,0) -> ACTIVO | C7: 1 | D7: =VLOOKUP(C7,'ACTIVOS CODIGO'!C:D,2,0) -> ACTIVO DEL TESORO = ACTIVO CORRIENTE | E7: 1 | F7: =VLOOKUP(E7,'ACTIVOS CODIGO'!E:F,2,0) -> ACTIVO DISPONIBLE | G7: 102 | H7: =VLOOKUP(G7,'PUB 21'!$A$1:$B$29,2,0) -> TESORERIA MUNICIPAL | M7: =CONCATENATE(TEXT(A7,"0"),"-",TEXT(C7,"0"),"-",TEXT(E7,"0"),"-",TEXT(LEFT(G7,2),"00"),"-",TEXT(RIGHT(G7,1),"0"),TEXT(I7,"0"),"-",TEXT(K7,"00")) -> 1-1-1-10-20-00 | N7: =IF(L7="",IF(J7="",IF(H7="",IF(F7="",IF(D7="",B7,D7),F7),H7),J7),L7) -> TESORERIA MUNICIPAL | O7: =IF(P7="",0,IF(M6=M7,IF(O6="",0,O6)+1,"")) -> 0 | Q7: =CONCATENATE(TEXT(A7,"0"),"-",TEXT(C7,"0"),"-",TEXT(E7,"0"),"-",TEXT(LEFT(G7,2),"00"),"-",TEXT(RIGHT(G7,1),"0"),TEXT(I7,"0"),"-",TEXT(K7,"00"),"-",TEXT(O7,"000")) -> 1-1-1-10-20-00-000 | R7: =IF(P7="",IF(L7="",IF(J7="",IF(H7="",IF(F7="",IF(D7="",B7,D7),F7),H7),J7),L7),P7) -> TESORERIA MUNICIPAL | S7: =CONCATENATE(TEXT(LEFT(G7,2),"00"),"-",TEXT(RIGHT(G7,1),"0")) -> 10-2 | T7: TESORERIA MUNICIPAL | U7: 102
A8: 1 | B8: =VLOOKUP(A8,'ACTIVOS CODIGO'!A:B,2,0) -> ACTIVO | C8: 1 | D8: =VLOOKUP(C8,'ACTIVOS CODIGO'!C:D,2,0) -> ACTIVO DEL TESORO = ACTIVO CORRIENTE | E8: 1 | F8: =VLOOKUP(E8,'ACTIVOS CODIGO'!E:F,2,0) -> ACTIVO DISPONIBLE | G8: 102 | H8: =VLOOKUP(G8,'PUB 21'!$A$1:$B$29,2,0) -> TESORERIA MUNICIPAL | I8: 1 | J8: BANCOS PUBLICOS Y PRIVADOS | M8: =CONCATENATE(TEXT(A8,"0"),"-",TEXT(C8,"0"),"-",TEXT(E8,"0"),"-",TEXT(LEFT(G8,2),"00"),"-",TEXT(RIGHT(G8,1),"0"),TEXT(I8,"0"),"-",TEXT(K8,"00")) -> 1-1-1-10-21-00 | N8: =IF(L8="",IF(J8="",IF(H8="",IF(F8="",IF(D8="",B8,D8),F8),H8),J8),L8) -> BANCOS PUBLICOS Y PRIVADOS | O8: =IF(P8="",0,IF(M7=M8,IF(O7="",0,O7)+1,"")) -> 0 | Q8: =CONCATENATE(TEXT(A8,"0"),"-",TEXT(C8,"0"),"-",TEXT(E8,"0"),"-",TEXT(LEFT(G8,2),"00"),"-",TEXT(RIGHT(G8,1),"0"),TEXT(I8,"0"),"-",TEXT(K8,"00"),"-",TEXT(O8,"000")) -> 1-1-1-10-21-00-000 | R8: =IF(P8="",IF(L8="",IF(J8="",IF(H8="",IF(F8="",IF(D8="",B8,D8),F8),H8),J8),L8),P8) -> BANCOS PUBLICOS Y PRIVADOS | T8: BANCOS PUBLICOS Y PRIVADOS | U8: 102
A9: 1 | B9: =VLOOKUP(A9,'ACTIVOS CODIGO'!A:B,2,0) -> ACTIVO | C9: 1 | D9: =VLOOKUP(C9,'ACTIVOS CODIGO'!C:D,2,0) -> ACTIVO DEL TESORO = ACTIVO CORRIENTE | E9: 1 | F9: =VLOOKUP(E9,'ACTIVOS CODIGO'!E:F,2,0) -> ACTIVO DISPONIBLE | G9: 102 | H9: =VLOOKUP(G9,'PUB 21'!$A$1:$B$29,2,0) -> TESORERIA MUNICIPAL | I9: 1 | J9: BANCOS PUBLICOS Y PRIVADOS | K9: 1 | L9: BANCO PUBLICO | M9: =CONCATENATE(TEXT(A9,"0"),"-",TEXT(C9,"0"),"-",TEXT(E9,"0"),"-",TEXT(LEFT(G9,2),"00"),"-",TEXT(RIGHT(G9,1),"0"),TEXT(I9,"0"),"-",TEXT(K9,"00")) -> 1-1-1-10-21-01 | N9: =IF(L9="",IF(J9="",IF(H9="",IF(F9="",IF(D9="",B9,D9),F9),H9),J9),L9) -> BANCO PUBLICO | O9: =IF(P9="",0,IF(M8=M9,IF(O8="",0,O8)+1,"")) -> 0 | Q9: =CONCATENATE(TEXT(A9,"0"),"-",TEXT(C9,"0"),"-",TEXT(E9,"0"),"-",TEXT(LEFT(G9,2),"00"),"-",TEXT(RIGHT(G9,1),"0"),TEXT(I9,"0"),"-",TEXT(K9,"00"),"-",TEXT(O9,"000")) -> 1-1-1-10-21-01-000 | R9: =IF(P9="",IF(L9="",IF(J9="",IF(H9="",IF(F9="",IF(D9="",B9,D9),F9),H9),J9),L9),P9) -> BANCO PUBLICO
A10: 1 | B10: =VLOOKUP(A10,'ACTIVOS CODIGO'!A:B,2,0) -> ACTIVO | C10: 1 | D10: =VLOOKUP(C10,'ACTIVOS CODIGO'!C:D,2,0) -> ACTIVO DEL TESORO = ACTIVO CORRIENTE | E10: 1 | F10: =VLOOKUP(E10,'ACTIVOS CODIGO'!E:F,2,0) -> ACTIVO DISPONIBLE | G10: 102 | H10: =VLOOKUP(G10,'PUB 21'!$A$1:$B$29,2,0) -> TESORERIA MUNICIPAL | I10: 1 | J10: BANCOS PUBLICOS Y PRIVADOS | K10: 1 | L10: BANCO PUBLICO | M10: =CONCATENATE(TEXT(A10,"0"),"-",TEXT(C10,"0"),"-",TEXT(E10,"0"),"-",TEXT(LEFT(G10,2),"00"),"-",TEXT(RIGHT(G10,1),"0"),TEXT(I10,"0"),"-",TEXT(K10,"00")) -> 1-1-1-10-21-01 | N10: =IF(L10="",IF(J10="",IF(H10="",IF(F10="",IF(D10="",B10,D10),F10),H10),J10),L10) -> BANCO PUBLICO | O10: =IF(P10="",0,IF(M9=M10,IF(O9="",0,O9)+1,"")) -> 1 | P10: I.M.C.P. 0601-0001-24-0014071948 | Q10: =CONCATENATE(TEXT(A10,"0"),"-",TEXT(C10,"0"),"-",TEXT(E10,"0"),"-",TEXT(LEFT(G10,2),"00"),"-",TEXT(RIGHT(G10,1),"0"),TEXT(I10,"0"),"-",TEXT(K10,"00"),"-",TEXT(O10,"000")) -> 1-1-1-10-21-01-001 | R10: =IF(P10="",IF(L10="",IF(J10="",IF(H10="",IF(F10="",IF(D10="",B10,D10),F10),H10),J10),L10),P10) -> I.M.C.P. 0601-0001-24-0014071948
A11: 1 | B11: =VLOOKUP(A11,'ACTIVOS CODIGO'!A:B,2,0) -> ACTIVO | C11: 1 | D11: =VLOOKUP(C11,'ACTIVOS CODIGO'!C:D,2,0) -> ACTIVO DEL TESORO = ACTIVO CORRIENTE | E11: 1 | F11: =VLOOKUP(E11,'ACTIVOS CODIGO'!E:F,2,0) -> ACTIVO DISPONIBLE | G11: 102 | H11: =VLOOKUP(G11,'PUB 21'!$A$1:$B$29,2,0) -> TESORERIA MUNICIPAL | I11: 1 | J11: BANCOS PUBLICOS Y PRIVADOS | K11: 1 | L11: BANCO PUBLICO | M11: =CONCATENATE(TEXT(A11,"0"),"-",TEXT(C11,"0"),"-",TEXT(E11,"0"),"-",TEXT(LEFT(G11,2),"00"),"-",TEXT(RIGHT(G11,1),"0"),TEXT(I11,"0"),"-",TEXT(K11,"00")) -> 1-1-1-10-21-01 | N11: =IF(L11="",IF(J11="",IF(H11="",IF(F11="",IF(D11="",B11,D11),F11),H11),J11),L11) -> BANCO PUBLICO | O11: =IF(P11="",0,IF(M10=M11,IF(O10="",0,O10)+1,"")) -> 2 | P11: VENEZUELA 0102-0762-200000039709 | Q11: =CONCATENATE(TEXT(A11,"0"),"-",TEXT(C11,"0"),"-",TEXT(E11,"0"),"-",TEXT(LEFT(G11,2),"00"),"-",TEXT(RIGHT(G11,1),"0"),TEXT(I11,"0"),"-",TEXT(K11,"00"),"-",TEXT(O11,"000")) -> 1-1-1-10-21-01-002 | R11: =IF(P11="",IF(L11="",IF(J11="",IF(H11="",IF(F11="",IF(D11="",B11,D11),F11),H11),J11),L11),P11) -> VENEZUELA 0102-0762-200000039709
A12: 1 | B12: =VLOOKUP(A12,'ACTIVOS CODIGO'!A:B,2,0) -> ACTIVO | C12: 1 | D12: =VLOOKUP(C12,'ACTIVOS CODIGO'!C:D,2,0) -> ACTIVO DEL TESORO = ACTIVO CORRIENTE | E12: 1 | F12: =VLOOKUP(E12,'ACTIVOS CODIGO'!E:F,2,0) -> ACTIVO DISPONIBLE | G12: 102 | H12: =VLOOKUP(G12,'PUB 21'!$A$1:$B$29,2,0) -> TESORERIA MUNICIPAL | I12: 1 | J12: BANCOS PUBLICOS Y PRIVADOS | K12: 1 | L12: BANCO PUBLICO | M12: =CONCATENATE(TEXT(A12,"0"),"-",TEXT(C12,"0"),"-",TEXT(E12,"0"),"-",TEXT(LEFT(G12,2),"00"),"-",TEXT(RIGHT(G12,1),"0"),TEXT(I12,"0"),"-",TEXT(K12,"00")) -> 1-1-1-10-21-01 | N12: =IF(L12="",IF(J12="",IF(H12="",IF(F12="",IF(D12="",B12,D12),F12),H12),J12),L12) -> BANCO PUBLICO | O12: =IF(P12="",0,IF(M11=M12,IF(O11="",0,O11)+1,"")) -> 3 | P12: TESORO 0163-0903-65-9033005695 | Q12: =CONCATENATE(TEXT(A12,"0"),"-",TEXT(C12,"0"),"-",TEXT(E12,"0"),"-",TEXT(LEFT(G12,2),"00"),"-",TEXT(RIGHT(G12,1),"0"),TEXT(I12,"0"),"-",TEXT(K12,"00"),"-",TEXT(O12,"000")) -> 1-1-1-10-21-01-003 | R12: =IF(P12="",IF(L12="",IF(J12="",IF(H12="",IF(F12="",IF(D12="",B12,D12),F12),H12),J12),L12),P12) -> TESORO 0163-0903-65-9033005695
A13: 1 | B13: =VLOOKUP(A13,'ACTIVOS CODIGO'!A:B,2,0) -> ACTIVO | C13: 1 | D13: =VLOOKUP(C13,'ACTIVOS CODIGO'!C:D,2,0) -> ACTIVO DEL TESORO = ACTIVO CORRIENTE | E13: 1 | F13: =VLOOKUP(E13,'ACTIVOS CODIGO'!E:F,2,0) -> ACTIVO DISPONIBLE | G13: 102 | H13: =VLOOKUP(G13,'PUB 21'!$A$1:$B$29,2,0) -> TESORERIA MUNICIPAL | I13: 1 | J13: BANCOS PUBLICOS Y PRIVADOS | K13: 1 | L13: BANCO PUBLICO | M13: =CONCATENATE(TEXT(A13,"0"),"-",TEXT(C13,"0"),"-",TEXT(E13,"0"),"-",TEXT(LEFT(G13,2),"00"),"-",TEXT(RIGHT(G13,1),"0"),TEXT(I13,"0"),"-",TEXT(K13,"00")) -> 1-1-1-10-21-01 | N13: =IF(L13="",IF(J13="",IF(H13="",IF(F13="",IF(D13="",B13,D13),F13),H13),J13),L13) -> BANCO PUBLICO | O13: =IF(P13="",0,IF(M12=M13,IF(O12="",0,O12)+1,"")) -> 4 | P13: VENEZUELA 0000059226 | Q13: =CONCATENATE(TEXT(A13,"0"),"-",TEXT(C13,"0"),"-",TEXT(E13,"0"),"-",TEXT(LEFT(G13,2),"00"),"-",TEXT(RIGHT(G13,1),"0"),TEXT(I13,"0"),"-",TEXT(K13,"00"),"-",TEXT(O13,"000")) -> 1-1-1-10-21-01-004 | R13: =IF(P13="",IF(L13="",IF(J13="",IF(H13="",IF(F13="",IF(D13="",B13,D13),F13),H13),J13),L13),P13) -> VENEZUELA 0000059226
A14: 1 | B14: =VLOOKUP(A14,'ACTIVOS CODIGO'!A:B,2,0) -> ACTIVO | C14: 1 | D14: =VLOOKUP(C14,'ACTIVOS CODIGO'!C:D,2,0) -> ACTIVO DEL TESORO = ACTIVO CORRIENTE | E14: 1 | F14: =VLOOKUP(E14,'ACTIVOS CODIGO'!E:F,2,0) -> ACTIVO DISPONIBLE | G14: 102 | H14: =VLOOKUP(G14,'PUB 21'!$A$1:$B$29,2,0) -> TESORERIA MUNICIPAL | I14: 1 | J14: BANCOS PUBLICOS Y PRIVADOS | K14: 1 | L14: BANCO PUBLICO | M14: =CONCATENATE(TEXT(A14,"0"),"-",TEXT(C14,"0"),"-",TEXT(E14,"0"),"-",TEXT(LEFT(G14,2),"00"),"-",TEXT(RIGHT(G14,1),"0"),TEXT(I14,"0"),"-",TEXT(K14,"00")) -> 1-1-1-10-21-01 | N14: =IF(L14="",IF(J14="",IF(H14="",IF(F14="",IF(D14="",B14,D14),F14),H14),J14),L14) -> BANCO PUBLICO | O14: =IF(P14="",0,IF(M13=M14,IF(O13="",0,O13)+1,"")) -> 5 | P14: I.M.C.P. 0014103444 CTA. GTOS. 2021 | Q14: =CONCATENATE(TEXT(A14,"0"),"-",TEXT(C14,"0"),"-",TEXT(E14,"0"),"-",TEXT(LEFT(G14,2),"00"),"-",TEXT(RIGHT(G14,1),"0"),TEXT(I14,"0"),"-",TEXT(K14,"00"),"-",TEXT(O14,"000")) -> 1-1-1-10-21-01-005 | R14: =IF(P14="",IF(L14="",IF(J14="",IF(H14="",IF(F14="",IF(D14="",B14,D14),F14),H14),J14),L14),P14) -> I.M.C.P. 0014103444 CTA. GTOS. 2021
A15: 1 | B15: =VLOOKUP(A15,'ACTIVOS CODIGO'!A:B,2,0) -> ACTIVO | C15: 1 | D15: =VLOOKUP(C15,'ACTIVOS CODIGO'!C:D,2,0) -> ACTIVO DEL TESORO = ACTIVO CORRIENTE | E15: 1 | F15: =VLOOKUP(E15,'ACTIVOS CODIGO'!E:F,2,0) -> ACTIVO DISPONIBLE | G15: 102 | H15: =VLOOKUP(G15,'PUB 21'!$A$1:$B$29,2,0) -> TESORERIA MUNICIPAL | I15: 1 | J15: BANCOS PUBLICOS Y PRIVADOS | K15: 1 | L15: BANCO PUBLICO | M15: =CONCATENATE(TEXT(A15,"0"),"-",TEXT(C15,"0"),"-",TEXT(E15,"0"),"-",TEXT(LEFT(G15,2),"00"),"-",TEXT(RIGHT(G15,1),"0"),TEXT(I15,"0"),"-",TEXT(K15,"00")) -> 1-1-1-10-21-01 | N15: =IF(L15="",IF(J15="",IF(H15="",IF(F15="",IF(D15="",B15,D15),F15),H15),J15),L15) -> BANCO PUBLICO | O15: =IF(P15="",0,IF(M14=M15,IF(O14="",0,O14)+1,"")) -> 6 | P15: IMCP 0014103451 FISCO MCPAL. 2021 | Q15: =CONCATENATE(TEXT(A15,"0"),"-",TEXT(C15,"0"),"-",TEXT(E15,"0"),"-",TEXT(LEFT(G15,2),"00"),"-",TEXT(RIGHT(G15,1),"0"),TEXT(I15,"0"),"-",TEXT(K15,"00"),"-",TEXT(O15,"000")) -> 1-1-1-10-21-01-006 | R15: =IF(P15="",IF(L15="",IF(J15="",IF(H15="",IF(F15="",IF(D15="",B15,D15),F15),H15),J15),L15),P15) -> IMCP 0014103451 FISCO MCPAL. 2021
A16: 1 | B16: =VLOOKUP(A16,'ACTIVOS CODIGO'!A:B,2,0) -> ACTIVO | C16: 1 | D16: =VLOOKUP(C16,'ACTIVOS CODIGO'!C:D,2,0) -> ACTIVO DEL TESORO = ACTIVO CORRIENTE | E16: 1 | F16: =VLOOKUP(E16,'ACTIVOS CODIGO'!E:F,2,0) -> ACTIVO DISPONIBLE | G16: 102 | H16: =VLOOKUP(G16,'PUB 21'!$A$1:$B$29,2,0) -> TESORERIA MUNICIPAL | I16: 1 | J16: BANCOS PUBLICOS Y PRIVADOS | K16: 1 | L16: BANCO PUBLICO | M16: =CONCATENATE(TEXT(A16,"0"),"-",TEXT(C16,"0"),"-",TEXT(E16,"0"),"-",TEXT(LEFT(G16,2),"00"),"-",TEXT(RIGHT(G16,1),"0"),TEXT(I16,"0"),"-",TEXT(K16,"00")) -> 1-1-1-10-21-01 | N16: =IF(L16="",IF(J16="",IF(H16="",IF(F16="",IF(D16="",B16,D16),F16),H16),J16),L16) -> BANCO PUBLICO | O16: =IF(P16="",0,IF(M15=M16,IF(O15="",0,O15)+1,"")) -> 7 | P16: I.M.C.P. 0601-0001-28-0014103519 IMP. Y RETENC. 2021 | Q16: =CONCATENATE(TEXT(A16,"0"),"-",TEXT(C16,"0"),"-",TEXT(E16,"0"),"-",TEXT(LEFT(G16,2),"00"),"-",TEXT(RIGHT(G16,1),"0"),TEXT(I16,"0"),"-",TEXT(K16,"00"),"-",TEXT(O16,"000")) -> 1-1-1-10-21-01-007 | R16: =IF(P16="",IF(L16="",IF(J16="",IF(H16="",IF(F16="",IF(D16="",B16,D16),F16),H16),J16),L16),P16) -> I.M.C.P. 0601-0001-28-0014103519 IMP. Y RETENC. 2021
A17: 1 | B17: =VLOOKUP(A17,'ACTIVOS CODIGO'!A:B,2,0) -> ACTIVO | C17: 1 | D17: =VLOOKUP(C17,'ACTIVOS CODIGO'!C:D,2,0) -> ACTIVO DEL TESORO = ACTIVO CORRIENTE | E17: 1 | F17: =VLOOKUP(E17,'ACTIVOS CODIGO'!E:F,2,0) -> ACTIVO DISPONIBLE | G17: 102 | H17: =VLOOKUP(G17,'PUB 21'!$A$1:$B$29,2,0) -> TESORERIA MUNICIPAL | I17: 1 | J17: BANCOS PUBLICOS Y PRIVADOS | K17: 1 | L17: BANCO PUBLICO | M17: =CONCATENATE(TEXT(A17,"0"),"-",TEXT(C17,"0"),"-",TEXT(E17,"0"),"-",TEXT(LEFT(G17,2),"00"),"-",TEXT(RIGHT(G17,1),"0"),TEXT(I17,"0"),"-",TEXT(K17,"00")) -> 1-1-1-10-21-01 | N17: =IF(L17="",IF(J17="",IF(H17="",IF(F17="",IF(D17="",B17,D17),F17),H17),J17),L17) -> BANCO PUBLICO | O17: =IF(P17="",0,IF(M16=M17,IF(O16="",0,O16)+1,"")) -> 8 | P17: I.M.C.P. 0014103501 RESERVAS 2021 | Q17: =CONCATENATE(TEXT(A17,"0"),"-",TEXT(C17,"0"),"-",TEXT(E17,"0"),"-",TEXT(LEFT(G17,2),"00"),"-",TEXT(RIGHT(G17,1),"0"),TEXT(I17,"0"),"-",TEXT(K17,"00"),"-",TEXT(O17,"000")) -> 1-1-1-10-21-01-008 | R17: =IF(P17="",IF(L17="",IF(J17="",IF(H17="",IF(F17="",IF(D17="",B17,D17),F17),H17),J17),L17),P17) -> I.M.C.P. 0014103501 RESERVAS 2021
A18: 1 | B18: =VLOOKUP(A18,'ACTIVOS CODIGO'!A:B,2,0) -> ACTIVO | C18: 1 | D18: =VLOOKUP(C18,'ACTIVOS CODIGO'!C:D,2,0) -> ACTIVO DEL TESORO = ACTIVO CORRIENTE | E18: 1 | F18: =VLOOKUP(E18,'ACTIVOS CODIGO'!E:F,2,0) -> ACTIVO DISPONIBLE | G18: 102 | H18: =VLOOKUP(G18,'PUB 21'!$A$1:$B$29,2,0) -> TESORERIA MUNICIPAL | I18: 1 | J18: BANCOS PUBLICOS Y PRIVADOS | K18: 1 | L18: BANCO PUBLICO | M18: =CONCATENATE(TEXT(A18,"0"),"-",TEXT(C18,"0"),"-",TEXT(E18,"0"),"-",TEXT(LEFT(G18,2),"00"),"-",TEXT(RIGHT(G18,1),"0"),TEXT(I18,"0"),"-",TEXT(K18,"00")) -> 1-1-1-10-21-01 | N18: =IF(L18="",IF(J18="",IF(H18="",IF(F18="",IF(D18="",B18,D18),F18),H18),J18),L18) -> BANCO PUBLICO | O18: =IF(P18="",0,IF(M17=M18,IF(O17="",0,O17)+1,"")) -> 9 | P18: I.M.C.P 0014103485 APOSTILLAMIENTO 2021 | Q18: =CONCATENATE(TEXT(A18,"0"),"-",TEXT(C18,"0"),"-",TEXT(E18,"0"),"-",TEXT(LEFT(G18,2),"00"),"-",TEXT(RIGHT(G18,1),"0"),TEXT(I18,"0"),"-",TEXT(K18,"00"),"-",TEXT(O18,"000")) -> 1-1-1-10-21-01-009 | R18: =IF(P18="",IF(L18="",IF(J18="",IF(H18="",IF(F18="",IF(D18="",B18,D18),F18),H18),J18),L18),P18) -> I.M.C.P 0014103485 APOSTILLAMIENTO 2021
A19: 1 | B19: =VLOOKUP(A19,'ACTIVOS CODIGO'!A:B,2,0) -> ACTIVO | C19: 1 | D19: =VLOOKUP(C19,'ACTIVOS CODIGO'!C:D,2,0) -> ACTIVO DEL TESORO = ACTIVO CORRIENTE | E19: 1 | F19: =VLOOKUP(E19,'ACTIVOS CODIGO'!E:F,2,0) -> ACTIVO DISPONIBLE | G19: 102 | H19: =VLOOKUP(G19,'PUB 21'!$A$1:$B$29,2,0) -> TESORERIA MUNICIPAL | I19: 1 | J19: BANCOS PUBLICOS Y PRIVADOS | K19: 1 | L19: BANCO PUBLICO | M19: =CONCATENATE(TEXT(A19,"0"),"-",TEXT(C19,"0"),"-",TEXT(E19,"0"),"-",TEXT(LEFT(G19,2),"00"),"-",TEXT(RIGHT(G19,1),"0"),TEXT(I19,"0"),"-",TEXT(K19,"00")) -> 1-1-1-10-21-01 | N19: =IF(L19="",IF(J19="",IF(H19="",IF(F19="",IF(D19="",B19,D19),F19),H19),J19),L19) -> BANCO PUBLICO | O19: =IF(P19="",0,IF(M18=M19,IF(O18="",0,O18)+1,"")) -> 10 | P19: I.M.C.P. 0014103493 FCI 2021 | Q19: =CONCATENATE(TEXT(A19,"0"),"-",TEXT(C19,"0"),"-",TEXT(E19,"0"),"-",TEXT(LEFT(G19,2),"00"),"-",TEXT(RIGHT(G19,1),"0"),TEXT(I19,"0"),"-",TEXT(K19,"00"),"-",TEXT(O19,"000")) -> 1-1-1-10-21-01-010 | R19: =IF(P19="",IF(L19="",IF(J19="",IF(H19="",IF(F19="",IF(D19="",B19,D19),F19),H19),J19),L19),P19) -> I.M.C.P. 0014103493 FCI 2021
A20: 1 | B20: =VLOOKUP(A20,'ACTIVOS CODIGO'!A:B,2,0) -> ACTIVO | C20: 1 | D20: =VLOOKUP(C20,'ACTIVOS CODIGO'!C:D,2,0) -> ACTIVO DEL TESORO = ACTIVO CORRIENTE | E20: 1 | F20: =VLOOKUP(E20,'ACTIVOS CODIGO'!E:F,2,0) -> ACTIVO DISPONIBLE | G20: 102 | H20: =VLOOKUP(G20,'PUB 21'!$A$1:$B$29,2,0) -> TESORERIA MUNICIPAL | I20: 1 | J20: BANCOS PUBLICOS Y PRIVADOS | K20: 1 | L20: BANCO PUBLICO | M20: =CONCATENATE(TEXT(A20,"0"),"-",TEXT(C20,"0"),"-",TEXT(E20,"0"),"-",TEXT(LEFT(G20,2),"00"),"-",TEXT(RIGHT(G20,1),"0"),TEXT(I20,"0"),"-",TEXT(K20,"00")) -> 1-1-1-10-21-01 | N20: =IF(L20="",IF(J20="",IF(H20="",IF(F20="",IF(D20="",B20,D20),F20),H20),J20),L20) -> BANCO PUBLICO | O20: =IF(P20="",0,IF(M19=M20,IF(O19="",0,O19)+1,"")) -> 11 | P20: I.M.C.P 0014103469 ING. EXT. 2021 | Q20: =CONCATENATE(TEXT(A20,"0"),"-",TEXT(C20,"0"),"-",TEXT(E20,"0"),"-",TEXT(LEFT(G20,2),"00"),"-",TEXT(RIGHT(G20,1),"0"),TEXT(I20,"0"),"-",TEXT(K20,"00"),"-",TEXT(O20,"000")) -> 1-1-1-10-21-01-011 | R20: =IF(P20="",IF(L20="",IF(J20="",IF(H20="",IF(F20="",IF(D20="",B20,D20),F20),H20),J20),L20),P20) -> I.M.C.P 0014103469 ING. EXT. 2021
A21: 1 | B21: =VLOOKUP(A21,'ACTIVOS CODIGO'!A:B,2,0) -> ACTIVO | C21: 1 | D21: =VLOOKUP(C21,'ACTIVOS CODIGO'!C:D,2,0) -> ACTIVO DEL TESORO = ACTIVO CORRIENTE | E21: 1 | F21: =VLOOKUP(E21,'ACTIVOS CODIGO'!E:F,2,0) -> ACTIVO DISPONIBLE | G21: 102 | H21: =VLOOKUP(G21,'PUB 21'!$A$1:$B$29,2,0) -> TESORERIA MUNICIPAL | I21: 1 | J21: BANCOS PUBLICOS Y PRIVADOS | K21: 1 | L21: BANCO PUBLICO | M21: =CONCATENATE(TEXT(A21,"0"),"-",TEXT(C21,"0"),"-",TEXT(E21,"0"),"-",TEXT(LEFT(G21,2),"00"),"-",TEXT(RIGHT(G21,1),"0"),TEXT(I21,"0"),"-",TEXT(K21,"00")) -> 1-1-1-10-21-01 | N21: =IF(L21="",IF(J21="",IF(H21="",IF(F21="",IF(D21="",B21,D21),F21),H21),J21),L21) -> BANCO PUBLICO | O21: =IF(P21="",0,IF(M20=M21,IF(O20="",0,O20)+1,"")) -> 12 | P21: I.M.C.P 0014106082 ING. NO TRIBUTARIOS 2021 | Q21: =CONCATENATE(TEXT(A21,"0"),"-",TEXT(C21,"0"),"-",TEXT(E21,"0"),"-",TEXT(LEFT(G21,2),"00"),"-",TEXT(RIGHT(G21,1),"0"),TEXT(I21,"0"),"-",TEXT(K21,"00"),"-",TEXT(O21,"000")) -> 1-1-1-10-21-01-012 | R21: =IF(P21="",IF(L21="",IF(J21="",IF(H21="",IF(F21="",IF(D21="",B21,D21),F21),H21),J21),L21),P21) -> I.M.C.P 0014106082 ING. NO TRIBUTARIOS 2021
... A49: 1 | B49: =VLOOKUP(A49,'ACTIVOS CODIGO'!A:B,2,0) -> ACTIVO | C49: 1 | D49: =VLOOKUP(C49,'ACTIVOS CODIGO'!C:D,2,0) -> ACTIVO DEL TESORO = ACTIVO CORRIENTE | E49: 1 | F49: =VLOOKUP(E49,'ACTIVOS CODIGO'!E:F,2,0) -> ACTIVO DISPONIBLE | G49: 102 | H49: =VLOOKUP(G49,'PUB 21'!$A$1:$B$29,2,0) -> TESORERIA MUNICIPAL | I49: 1 | J49: BANCOS PUBLICOS Y PRIVADOS | K49: 1 | L49: BANCO PUBLICO | M49: =CONCATENATE(TEXT(A49,"0"),"-",TEXT(C49,"0"),"-",TEXT(E49,"0"),"-",TEXT(LEFT(G49,2),"00"),"-",TEXT(RIGHT(G49,1),"0"),TEXT(I49,"0"),"-",TEXT(K49,"00")) -> 1-1-1-10-21-01 | N49: =IF(L49="",IF(J49="",IF(H49="",IF(F49="",IF(D49="",B49,D49),F49),H49),J49),L49) -> BANCO PUBLICO | O49: =IF(P49="",0,IF(M48=M49,IF(O48="",0,O48)+1,"")) -> 40 | P49: PARTIDA POR CERTIFICAR VENEZUELA | Q49: =CONCATENATE(TEXT(A49,"0"),"-",TEXT(C49,"0"),"-",TEXT(E49,"0"),"-",TEXT(LEFT(G49,2),"00"),"-",TEXT(RIGHT(G49,1),"0"),TEXT(I49,"0"),"-",TEXT(K49,"00"),"-",TEXT(O49,"000")) -> 1-1-1-10-21-01-040 | R49: =IF(P49="",IF(L49="",IF(J49="",IF(H49="",IF(F49="",IF(D49="",B49,D49),F49),H49),J49),L49),P49) -> PARTIDA POR CERTIFICAR VENEZUELA
A50: 1 | B50: =VLOOKUP(A50,'ACTIVOS CODIGO'!A:B,2,0) -> ACTIVO | C50: 1 | D50: =VLOOKUP(C50,'ACTIVOS CODIGO'!C:D,2,0) -> ACTIVO DEL TESORO = ACTIVO CORRIENTE | E50: 1 | F50: =VLOOKUP(E50,'ACTIVOS CODIGO'!E:F,2,0) -> ACTIVO DISPONIBLE | G50: 102 | H50: =VLOOKUP(G50,'PUB 21'!$A$1:$B$29,2,0) -> TESORERIA MUNICIPAL | I50: 1 | J50: BANCOS PUBLICOS Y PRIVADOS | K50: 2 | L50: BANCO PRIVADO | M50: =CONCATENATE(TEXT(A50,"0"),"-",TEXT(C50,"0"),"-",TEXT(E50,"0"),"-",TEXT(LEFT(G50,2),"00"),"-",TEXT(RIGHT(G50,1),"0"),TEXT(I50,"0"),"-",TEXT(K50,"00")) -> 1-1-1-10-21-02 | N50: =IF(L50="",IF(J50="",IF(H50="",IF(F50="",IF(D50="",B50,D50),F50),H50),J50),L50) -> BANCO PRIVADO | O50: =IF(P50="",0,IF(M49=M50,IF(O49="",0,O49)+1,"")) -> 0 | Q50: =CONCATENATE(TEXT(A50,"0"),"-",TEXT(C50,"0"),"-",TEXT(E50,"0"),"-",TEXT(LEFT(G50,2),"00"),"-",TEXT(RIGHT(G50,1),"0"),TEXT(I50,"0"),"-",TEXT(K50,"00"),"-",TEXT(O50,"000")) -> 1-1-1-10-21-02-000 | R50: =IF(P50="",IF(L50="",IF(J50="",IF(H50="",IF(F50="",IF(D50="",B50,D50),F50),H50),J50),L50),P50) -> BANCO PRIVADO
A51: 1 | B51: =VLOOKUP(A51,'ACTIVOS CODIGO'!A:B,2,0) -> ACTIVO | C51: 1 | D51: =VLOOKUP(C51,'ACTIVOS CODIGO'!C:D,2,0) -> ACTIVO DEL TESORO = ACTIVO CORRIENTE | E51: 1 | F51: =VLOOKUP(E51,'ACTIVOS CODIGO'!E:F,2,0) -> ACTIVO DISPONIBLE | G51: 102 | H51: =VLOOKUP(G51,'PUB 21'!$A$1:$B$29,2,0) -> TESORERIA MUNICIPAL | I51: 1 | J51: BANCOS PUBLICOS Y PRIVADOS | K51: 2 | L51: BANCO PRIVADO | M51: =CONCATENATE(TEXT(A51,"0"),"-",TEXT(C51,"0"),"-",TEXT(E51,"0"),"-",TEXT(LEFT(G51,2),"00"),"-",TEXT(RIGHT(G51,1),"0"),TEXT(I51,"0"),"-",TEXT(K51,"00")) -> 1-1-1-10-21-02 | N51: =IF(L51="",IF(J51="",IF(H51="",IF(F51="",IF(D51="",B51,D51),F51),H51),J51),L51) -> BANCO PRIVADO | O51: =IF(P51="",0,IF(M50=M51,IF(O50="",0,O50)+1,"")) -> 1 | P51: BANESCO 0134-0031-89-0311159052 | Q51: =CONCATENATE(TEXT(A51,"0"),"-",TEXT(C51,"0"),"-",TEXT(E51,"0"),"-",TEXT(LEFT(G51,2),"00"),"-",TEXT(RIGHT(G51,1),"0"),TEXT(I51,"0"),"-",TEXT(K51,"00"),"-",TEXT(O51,"000")) -> 1-1-1-10-21-02-001 | R51: =IF(P51="",IF(L51="",IF(J51="",IF(H51="",IF(F51="",IF(D51="",B51,D51),F51),H51),J51),L51),P51) -> BANESCO 0134-0031-89-0311159052
A52: 1 | B52: =VLOOKUP(A52,'ACTIVOS CODIGO'!A:B,2,0) -> ACTIVO | C52: 1 | D52: =VLOOKUP(C52,'ACTIVOS CODIGO'!C:D,2,0) -> ACTIVO DEL TESORO = ACTIVO CORRIENTE | E52: 1 | F52: =VLOOKUP(E52,'ACTIVOS CODIGO'!E:F,2,0) -> ACTIVO DISPONIBLE | G52: 102 | H52: =VLOOKUP(G52,'PUB 21'!$A$1:$B$29,2,0) -> TESORERIA MUNICIPAL | I52: 1 | J52: BANCOS PUBLICOS Y PRIVADOS | K52: 2 | L52: BANCO PRIVADO | M52: =CONCATENATE(TEXT(A52,"0"),"-",TEXT(C52,"0"),"-",TEXT(E52,"0"),"-",TEXT(LEFT(G52,2),"00"),"-",TEXT(RIGHT(G52,1),"0"),TEXT(I52,"0"),"-",TEXT(K52,"00")) -> 1-1-1-10-21-02 | N52: =IF(L52="",IF(J52="",IF(H52="",IF(F52="",IF(D52="",B52,D52),F52),H52),J52),L52) -> BANCO PRIVADO | O52: =IF(P52="",0,IF(M51=M52,IF(O51="",0,O51)+1,"")) -> 2 | P52: B.O.D. 0116-0032-85-0028290615 | Q52: =CONCATENATE(TEXT(A52,"0"),"-",TEXT(C52,"0"),"-",TEXT(E52,"0"),"-",TEXT(LEFT(G52,2),"00"),"-",TEXT(RIGHT(G52,1),"0"),TEXT(I52,"0"),"-",TEXT(K52,"00"),"-",TEXT(O52,"000")) -> 1-1-1-10-21-02-002 | R52: =IF(P52="",IF(L52="",IF(J52="",IF(H52="",IF(F52="",IF(D52="",B52,D52),F52),H52),J52),L52),P52) -> B.O.D. 0116-0032-85-0028290615
A53: 1 | B53: =VLOOKUP(A53,'ACTIVOS CODIGO'!A:B,2,0) -> ACTIVO | C53: 1 | D53: =VLOOKUP(C53,'ACTIVOS CODIGO'!C:D,2,0) -> ACTIVO DEL TESORO = ACTIVO CORRIENTE | E53: 1 | F53: =VLOOKUP(E53,'ACTIVOS CODIGO'!E:F,2,0) -> ACTIVO DISPONIBLE | G53: 102 | H53: =VLOOKUP(G53,'PUB 21'!$A$1:$B$29,2,0) -> TESORERIA MUNICIPAL | I53: 1 | J53: BANCOS PUBLICOS Y PRIVADOS | K53: 2 | L53: BANCO PRIVADO | M53: =CONCATENATE(TEXT(A53,"0"),"-",TEXT(C53,"0"),"-",TEXT(E53,"0"),"-",TEXT(LEFT(G53,2),"00"),"-",TEXT(RIGHT(G53,1),"0"),TEXT(I53,"0"),"-",TEXT(K53,"00")) -> 1-1-1-10-21-02 | N53: =IF(L53="",IF(J53="",IF(H53="",IF(F53="",IF(D53="",B53,D53),F53),H53),J53),L53) -> BANCO PRIVADO | O53: =IF(P53="",0,IF(M52=M53,IF(O52="",0,O52)+1,"")) -> 3 | P53: PROVINCIAL 0108-0582-21-9010005000 | Q53: =CONCATENATE(TEXT(A53,"0"),"-",TEXT(C53,"0"),"-",TEXT(E53,"0"),"-",TEXT(LEFT(G53,2),"00"),"-",TEXT(RIGHT(G53,1),"0"),TEXT(I53,"0"),"-",TEXT(K53,"00"),"-",TEXT(O53,"000")) -> 1-1-1-10-21-02-003 | R53: =IF(P53="",IF(L53="",IF(J53="",IF(H53="",IF(F53="",IF(D53="",B53,D53),F53),H53),J53),L53),P53) -> PROVINCIAL 0108-0582-21-9010005000
A54: 1 | B54: =VLOOKUP(A54,'ACTIVOS CODIGO'!A:B,2,0) -> ACTIVO | C54: 1 | D54: =VLOOKUP(C54,'ACTIVOS CODIGO'!C:D,2,0) -> ACTIVO DEL TESORO = ACTIVO CORRIENTE | E54: 1 | F54: =VLOOKUP(E54,'ACTIVOS CODIGO'!E:F,2,0) -> ACTIVO DISPONIBLE | G54: 102 | H54: =VLOOKUP(G54,'PUB 21'!$A$1:$B$29,2,0) -> TESORERIA MUNICIPAL | I54: 1 | J54: BANCOS PUBLICOS Y PRIVADOS | K54: 2 | L54: BANCO PRIVADO | M54: =CONCATENATE(TEXT(A54,"0"),"-",TEXT(C54,"0"),"-",TEXT(E54,"0"),"-",TEXT(LEFT(G54,2),"00"),"-",TEXT(RIGHT(G54,1),"0"),TEXT(I54,"0"),"-",TEXT(K54,"00")) -> 1-1-1-10-21-02 | N54: =IF(L54="",IF(J54="",IF(H54="",IF(F54="",IF(D54="",B54,D54),F54),H54),J54),L54) -> BANCO PRIVADO | O54: =IF(P54="",0,IF(M53=M54,IF(O53="",0,O53)+1,"")) -> 4 | P54: FONDO COMUN 0151-0100-85-3000872449 | Q54: =CONCATENATE(TEXT(A54,"0"),"-",TEXT(C54,"0"),"-",TEXT(E54,"0"),"-",TEXT(LEFT(G54,2),"00"),"-",TEXT(RIGHT(G54,1),"0"),TEXT(I54,"0"),"-",TEXT(K54,"00"),"-",TEXT(O54,"000")) -> 1-1-1-10-21-02-004 | R54: =IF(P54="",IF(L54="",IF(J54="",IF(H54="",IF(F54="",IF(D54="",B54,D54),F54),H54),J54),L54),P54) -> FONDO COMUN 0151-0100-85-3000872449
A55: 1 | B55: =VLOOKUP(A55,'ACTIVOS CODIGO'!A:B,2,0) -> ACTIVO | C55: 1 | D55: =VLOOKUP(C55,'ACTIVOS CODIGO'!C:D,2,0) -> ACTIVO DEL TESORO = ACTIVO CORRIENTE | E55: 1 | F55: =VLOOKUP(E55,'ACTIVOS CODIGO'!E:F,2,0) -> ACTIVO DISPONIBLE | G55: 102 | H55: =VLOOKUP(G55,'PUB 21'!$A$1:$B$29,2,0) -> TESORERIA MUNICIPAL | I55: 1 | J55: BANCOS PUBLICOS Y PRIVADOS | K55: 2 | L55: BANCO PRIVADO | M55: =CONCATENATE(TEXT(A55,"0"),"-",TEXT(C55,"0"),"-",TEXT(E55,"0"),"-",TEXT(LEFT(G55,2),"00"),"-",TEXT(RIGHT(G55,1),"0"),TEXT(I55,"0"),"-",TEXT(K55,"00")) -> 1-1-1-10-21-02 | N55: =IF(L55="",IF(J55="",IF(H55="",IF(F55="",IF(D55="",B55,D55),F55),H55),J55),L55) -> BANCO PRIVADO | O55: =IF(P55="",0,IF(M54=M55,IF(O54="",0,O54)+1,"")) -> 5 | P55: 0102-0762-210000050322 | Q55: =CONCATENATE(TEXT(A55,"0"),"-",TEXT(C55,"0"),"-",TEXT(E55,"0"),"-",TEXT(LEFT(G55,2),"00"),"-",TEXT(RIGHT(G55,1),"0"),TEXT(I55,"0"),"-",TEXT(K55,"00"),"-",TEXT(O55,"000")) -> 1-1-1-10-21-02-005 | R55: =IF(P55="",IF(L55="",IF(J55="",IF(H55="",IF(F55="",IF(D55="",B55,D55),F55),H55),J55),L55),P55) -> 0102-0762-210000050322
A56: 1 | B56: =VLOOKUP(A56,'ACTIVOS CODIGO'!A:B,2,0) -> ACTIVO | C56: 1 | D56: =VLOOKUP(C56,'ACTIVOS CODIGO'!C:D,2,0) -> ACTIVO DEL TESORO = ACTIVO CORRIENTE | E56: 1 | F56: =VLOOKUP(E56,'ACTIVOS CODIGO'!E:F,2,0) -> ACTIVO DISPONIBLE | G56: 102 | H56: =VLOOKUP(G56,'PUB 21'!$A$1:$B$29,2,0) -> TESORERIA MUNICIPAL | I56: 1 | J56: BANCOS PUBLICOS Y PRIVADOS | K56: 2 | L56: BANCO PRIVADO | M56: =CONCATENATE(TEXT(A56,"0"),"-",TEXT(C56,"0"),"-",TEXT(E56,"0"),"-",TEXT(LEFT(G56,2),"00"),"-",TEXT(RIGHT(G56,1),"0"),TEXT(I56,"0"),"-",TEXT(K56,"00")) -> 1-1-1-10-21-02 | N56: =IF(L56="",IF(J56="",IF(H56="",IF(F56="",IF(D56="",B56,D56),F56),H56),J56),L56) -> BANCO PRIVADO | O56: =IF(P56="",0,IF(M55=M56,IF(O55="",0,O55)+1,"")) -> 6 | P56: I.M.C.P 0601-0001-21-0014098545 | Q56: =CONCATENATE(TEXT(A56,"0"),"-",TEXT(C56,"0"),"-",TEXT(E56,"0"),"-",TEXT(LEFT(G56,2),"00"),"-",TEXT(RIGHT(G56,1),"0"),TEXT(I56,"0"),"-",TEXT(K56,"00"),"-",TEXT(O56,"000")) -> 1-1-1-10-21-02-006 | R56: =IF(P56="",IF(L56="",IF(J56="",IF(H56="",IF(F56="",IF(D56="",B56,D56),F56),H56),J56),L56),P56) -> I.M.C.P 0601-0001-21-0014098545
A57: 1 | B57: =VLOOKUP(A57,'ACTIVOS CODIGO'!A:B,2,0) -> ACTIVO | C57: 1 | D57: =VLOOKUP(C57,'ACTIVOS CODIGO'!C:D,2,0) -> ACTIVO DEL TESORO = ACTIVO CORRIENTE | E57: 1 | F57: =VLOOKUP(E57,'ACTIVOS CODIGO'!E:F,2,0) -> ACTIVO DISPONIBLE | G57: 102 | H57: =VLOOKUP(G57,'PUB 21'!$A$1:$B$29,2,0) -> TESORERIA MUNICIPAL | I57: 1 | J57: BANCOS PUBLICOS Y PRIVADOS | K57: 2 | L57: BANCO PRIVADO | M57: =CONCATENATE(TEXT(A57,"0"),"-",TEXT(C57,"0"),"-",TEXT(E57,"0"),"-",TEXT(LEFT(G57,2),"00"),"-",TEXT(RIGHT(G57,1),"0"),TEXT(I57,"0"),"-",TEXT(K57,"00")) -> 1-1-1-10-21-02 | N57: =IF(L57="",IF(J57="",IF(H57="",IF(F57="",IF(D57="",B57,D57),F57),H57),J57),L57) -> BANCO PRIVADO | O57: =IF(P57="",0,IF(M56=M57,IF(O56="",0,O56)+1,"")) -> 7 | P57: BNC 01168884 | Q57: =CONCATENATE(TEXT(A57,"0"),"-",TEXT(C57,"0"),"-",TEXT(E57,"0"),"-",TEXT(LEFT(G57,2),"00"),"-",TEXT(RIGHT(G57,1),"0"),TEXT(I57,"0"),"-",TEXT(K57,"00"),"-",TEXT(O57,"000")) -> 1-1-1-10-21-02-007 | R57: =IF(P57="",IF(L57="",IF(J57="",IF(H57="",IF(F57="",IF(D57="",B57,D57),F57),H57),J57),L57),P57) -> BNC 01168884
A58: 1 | B58: =VLOOKUP(A58,'ACTIVOS CODIGO'!A:B,2,0) -> ACTIVO | C58: 1 | D58: =VLOOKUP(C58,'ACTIVOS CODIGO'!C:D,2,0) -> ACTIVO DEL TESORO = ACTIVO CORRIENTE | E58: 1 | F58: =VLOOKUP(E58,'ACTIVOS CODIGO'!E:F,2,0) -> ACTIVO DISPONIBLE | G58: 102 | H58: =VLOOKUP(G58,'PUB 21'!$A$1:$B$29,2,0) -> TESORERIA MUNICIPAL | I58: 1 | J58: BANCOS PUBLICOS Y PRIVADOS | K58: 2 | L58: BANCO PRIVADO | M58: =CONCATENATE(TEXT(A58,"0"),"-",TEXT(C58,"0"),"-",TEXT(E58,"0"),"-",TEXT(LEFT(G58,2),"00"),"-",TEXT(RIGHT(G58,1),"0"),TEXT(I58,"0"),"-",TEXT(K58,"00")) -> 1-1-1-10-21-02 | N58: =IF(L58="",IF(J58="",IF(H58="",IF(F58="",IF(D58="",B58,D58),F58),H58),J58),L58) -> BANCO PRIVADO | O58: =IF(P58="",0,IF(M57=M58,IF(O57="",0,O57)+1,"")) -> 8 | P58: BANCARIBE 0114015977 1590175737 | Q58: =CONCATENATE(TEXT(A58,"0"),"-",TEXT(C58,"0"),"-",TEXT(E58,"0"),"-",TEXT(LEFT(G58,2),"00"),"-",TEXT(RIGHT(G58,1),"0"),TEXT(I58,"0"),"-",TEXT(K58,"00"),"-",TEXT(O58,"000")) -> 1-1-1-10-21-02-008 | R58: =IF(P58="",IF(L58="",IF(J58="",IF(H58="",IF(F58="",IF(D58="",B58,D58),F58),H58),J58),L58),P58) -> BANCARIBE 0114015977 1590175737
A59: 1 | B59: =VLOOKUP(A59,'ACTIVOS CODIGO'!A:B,2,0) -> ACTIVO | C59: 1 | D59: =VLOOKUP(C59,'ACTIVOS CODIGO'!C:D,2,0) -> ACTIVO DEL TESORO = ACTIVO CORRIENTE | E59: 1 | F59: =VLOOKUP(E59,'ACTIVOS CODIGO'!E:F,2,0) -> ACTIVO DISPONIBLE | G59: 102 | H59: =VLOOKUP(G59,'PUB 21'!$A$1:$B$29,2,0) -> TESORERIA MUNICIPAL | I59: 1 | J59: BANCOS PUBLICOS Y PRIVADOS | K59: 2 | L59: BANCO PRIVADO | M59: =CONCATENATE(TEXT(A59,"0"),"-",TEXT(C59,"0"),"-",TEXT(E59,"0"),"-",TEXT(LEFT(G59,2),"00"),"-",TEXT(RIGHT(G59,1),"0"),TEXT(I59,"0"),"-",TEXT(K59,"00")) -> 1-1-1-10-21-02 | N59: =IF(L59="",IF(J59="",IF(H59="",IF(F59="",IF(D59="",B59,D59),F59),H59),J59),L59) -> BANCO PRIVADO | O59: =IF(P59="",0,IF(M58=M59,IF(O58="",0,O58)+1,"")) -> 9 | P59: FONDO COMUN 300077149 | Q59: =CONCATENATE(TEXT(A59,"0"),"-",TEXT(C59,"0"),"-",TEXT(E59,"0"),"-",TEXT(LEFT(G59,2),"00"),"-",TEXT(RIGHT(G59,1),"0"),TEXT(I59,"0"),"-",TEXT(K59,"00"),"-",TEXT(O59,"000")) -> 1-1-1-10-21-02-009 | R59: =IF(P59="",IF(L59="",IF(J59="",IF(H59="",IF(F59="",IF(D59="",B59,D59),F59),H59),J59),L59),P59) -> FONDO COMUN 300077149
A60: 1 | B60: =VLOOKUP(A60,'ACTIVOS CODIGO'!A:B,2,0) -> ACTIVO | C60: 1 | D60: =VLOOKUP(C60,'ACTIVOS CODIGO'!C:D,2,0) -> ACTIVO DEL TESORO = ACTIVO CORRIENTE | E60: 1 | F60: =VLOOKUP(E60,'ACTIVOS CODIGO'!E:F,2,0) -> ACTIVO DISPONIBLE | G60: 102 | H60: =VLOOKUP(G60,'PUB 21'!$A$1:$B$29,2,0) -> TESORERIA MUNICIPAL | I60: 1 | J60: BANCOS PUBLICOS Y PRIVADOS | K60: 2 | L60: BANCO PRIVADO | M60: =CONCATENATE(TEXT(A60,"0"),"-",TEXT(C60,"0"),"-",TEXT(E60,"0"),"-",TEXT(LEFT(G60,2),"00"),"-",TEXT(RIGHT(G60,1),"0"),TEXT(I60,"0"),"-",TEXT(K60,"00")) -> 1-1-1-10-21-02 | N60: =IF(L60="",IF(J60="",IF(H60="",IF(F60="",IF(D60="",B60,D60),F60),H60),J60),L60) -> BANCO PRIVADO | O60: =IF(P60="",0,IF(M59=M60,IF(O59="",0,O59)+1,"")) -> 10 | P60: BANESCO CUENTA CORRIENTE 4782 | Q60: =CONCATENATE(TEXT(A60,"0"),"-",TEXT(C60,"0"),"-",TEXT(E60,"0"),"-",TEXT(LEFT(G60,2),"00"),"-",TEXT(RIGHT(G60,1),"0"),TEXT(I60,"0"),"-",TEXT(K60,"00"),"-",TEXT(O60,"000")) -> 1-1-1-10-21-02-010 | R60: =IF(P60="",IF(L60="",IF(J60="",IF(H60="",IF(F60="",IF(D60="",B60,D60),F60),H60),J60),L60),P60) -> BANESCO CUENTA CORRIENTE 4782
A61: 1 | B61: =VLOOKUP(A61,'ACTIVOS CODIGO'!A:B,2,0) -> ACTIVO | C61: 1 | D61: =VLOOKUP(C61,'ACTIVOS CODIGO'!C:D,2,0) -> ACTIVO DEL TESORO = ACTIVO CORRIENTE | E61: 1 | F61: =VLOOKUP(E61,'ACTIVOS CODIGO'!E:F,2,0) -> ACTIVO DISPONIBLE | G61: 102 | H61: =VLOOKUP(G61,'PUB 21'!$A$1:$B$29,2,0) -> TESORERIA MUNICIPAL | I61: 1 | J61: BANCOS PUBLICOS Y PRIVADOS | K61: 2 | L61: BANCO PRIVADO | M61: =CONCATENATE(TEXT(A61,"0"),"-",TEXT(C61,"0"),"-",TEXT(E61,"0"),"-",TEXT(LEFT(G61,2),"00"),"-",TEXT(RIGHT(G61,1),"0"),TEXT(I61,"0"),"-",TEXT(K61,"00")) -> 1-1-1-10-21-02 | N61: =IF(L61="",IF(J61="",IF(H61="",IF(F61="",IF(D61="",B61,D61),F61),H61),J61),L61) -> BANCO PRIVADO | O61: =IF(P61="",0,IF(M60=M61,IF(O60="",0,O60)+1,"")) -> 11 | P61: BANCARIBE 0114-0159-76-1590175990 CTA. GASTOS 2021 | Q61: =CONCATENATE(TEXT(A61,"0"),"-",TEXT(C61,"0"),"-",TEXT(E61,"0"),"-",TEXT(LEFT(G61,2),"00"),"-",TEXT(RIGHT(G61,1),"0"),TEXT(I61,"0"),"-",TEXT(K61,"00"),"-",TEXT(O61,"000")) -> 1-1-1-10-21-02-011 | R61: =IF(P61="",IF(L61="",IF(J61="",IF(H61="",IF(F61="",IF(D61="",B61,D61),F61),H61),J61),L61),P61) -> BANCARIBE 0114-0159-76-1590175990 CTA. GASTOS 2021
A62: 1 | B62: =VLOOKUP(A62,'ACTIVOS CODIGO'!A:B,2,0) -> ACTIVO | C62: 1 | D62: =VLOOKUP(C62,'ACTIVOS CODIGO'!C:D,2,0) -> ACTIVO DEL TESORO = ACTIVO CORRIENTE | E62: 1 | F62: =VLOOKUP(E62,'ACTIVOS CODIGO'!E:F,2,0) -> ACTIVO DISPONIBLE | G62: 102 | H62: =VLOOKUP(G62,'PUB 21'!$A$1:$B$29,2,0) -> TESORERIA MUNICIPAL | I62: 1 | J62: BANCOS PUBLICOS Y PRIVADOS | K62: 2 | L62: BANCO PRIVADO | M62: =CONCATENATE(TEXT(A62,"0"),"-",TEXT(C62,"0"),"-",TEXT(E62,"0"),"-",TEXT(LEFT(G62,2),"00"),"-",TEXT(RIGHT(G62,1),"0"),TEXT(I62,"0"),"-",TEXT(K62,"00")) -> 1-1-1-10-21-02 | N62: =IF(L62="",IF(J62="",IF(H62="",IF(F62="",IF(D62="",B62,D62),F62),H62),J62),L62) -> BANCO PRIVADO | O62: =IF(P62="",0,IF(M61=M62,IF(O61="",0,O61)+1,"")) -> 12 | P62: BANCARIBE 1590176008 FISCO MUNICIPAL 2021 | Q62: =CONCATENATE(TEXT(A62,"0"),"-",TEXT(C62,"0"),"-",TEXT(E62,"0"),"-",TEXT(LEFT(G62,2),"00"),"-",TEXT(RIGHT(G62,1),"0"),TEXT(I62,"0"),"-",TEXT(K62,"00"),"-",TEXT(O62,"000")) -> 1-1-1-10-21-02-012 | R62: =IF(P62="",IF(L62="",IF(J62="",IF(H62="",IF(F62="",IF(D62="",B62,D62),F62),H62),J62),L62),P62) -> BANCARIBE 1590176008 FISCO MUNICIPAL 2021
... A76: 1 | B76: =VLOOKUP(A76,'ACTIVOS CODIGO'!A:B,2,0) -> ACTIVO | C76: 1 | D76: =VLOOKUP(C76,'ACTIVOS CODIGO'!C:D,2,0) -> ACTIVO DEL TESORO = ACTIVO CORRIENTE | E76: 1 | F76: =VLOOKUP(E76,'ACTIVOS CODIGO'!E:F,2,0) -> ACTIVO DISPONIBLE | G76: 102 | H76: =VLOOKUP(G76,'PUB 21'!$A$1:$B$29,2,0) -> TESORERIA MUNICIPAL | I76: 1 | J76: BANCOS PUBLICOS Y PRIVADOS | K76: 2 | L76: BANCO PRIVADO | M76: =CONCATENATE(TEXT(A76,"0"),"-",TEXT(C76,"0"),"-",TEXT(E76,"0"),"-",TEXT(LEFT(G76,2),"00"),"-",TEXT(RIGHT(G76,1),"0"),TEXT(I76,"0"),"-",TEXT(K76,"00")) -> 1-1-1-10-21-02 | N76: =IF(L76="",IF(J76="",IF(H76="",IF(F76="",IF(D76="",B76,D76),F76),H76),J76),L76) -> BANCO PRIVADO | O76: =IF(P76="",0,IF(M75=M76,IF(O75="",0,O75)+1,"")) -> 26 | P76: PARTIDA POR CERTIFICAR BANESCO | Q76: =CONCATENATE(TEXT(A76,"0"),"-",TEXT(C76,"0"),"-",TEXT(E76,"0"),"-",TEXT(LEFT(G76,2),"00"),"-",TEXT(RIGHT(G76,1),"0"),TEXT(I76,"0"),"-",TEXT(K76,"00"),"-",TEXT(O76,"000")) -> 1-1-1-10-21-02-026 | R76: =IF(P76="",IF(L76="",IF(J76="",IF(H76="",IF(F76="",IF(D76="",B76,D76),F76),H76),J76),L76),P76) -> PARTIDA POR CERTIFICAR BANESCO
A77: 1 | B77: =VLOOKUP(A77,'ACTIVOS CODIGO'!A:B,2,0) -> ACTIVO | C77: 1 | D77: =VLOOKUP(C77,'ACTIVOS CODIGO'!C:D,2,0) -> ACTIVO DEL TESORO = ACTIVO CORRIENTE | E77: 1 | F77: =VLOOKUP(E77,'ACTIVOS CODIGO'!E:F,2,0) -> ACTIVO DISPONIBLE | G77: 110 | H77: =VLOOKUP(G77,'PUB 21'!$A$1:$B$29,2,0) -> FONDOS DEL SITUADO COORDINADO | M77: =CONCATENATE(TEXT(A77,"0"),"-",TEXT(C77,"0"),"-",TEXT(E77,"0"),"-",TEXT(LEFT(G77,2),"00"),"-",TEXT(RIGHT(G77,1),"0"),TEXT(I77,"0"),"-",TEXT(K77,"00")) -> 1-1-1-11-00-00 | N77: =IF(L77="",IF(J77="",IF(H77="",IF(F77="",IF(D77="",B77,D77),F77),H77),J77),L77) -> FONDOS DEL SITUADO COORDINADO | O77: =IF(P77="",0,IF(M76=M77,IF(O76="",0,O76)+1,"")) -> 0 | Q77: =CONCATENATE(TEXT(A77,"0"),"-",TEXT(C77,"0"),"-",TEXT(E77,"0"),"-",TEXT(LEFT(G77,2),"00"),"-",TEXT(RIGHT(G77,1),"0"),TEXT(I77,"0"),"-",TEXT(K77,"00"),"-",TEXT(O77,"000")) -> 1-1-1-11-00-00-000 | R77: =IF(P77="",IF(L77="",IF(J77="",IF(H77="",IF(F77="",IF(D77="",B77,D77),F77),H77),J77),L77),P77) -> FONDOS DEL SITUADO COORDINADO
A78: 1 | B78: =VLOOKUP(A78,'ACTIVOS CODIGO'!A:B,2,0) -> ACTIVO | C78: 1 | D78: =VLOOKUP(C78,'ACTIVOS CODIGO'!C:D,2,0) -> ACTIVO DEL TESORO = ACTIVO CORRIENTE | E78: 1 | F78: =VLOOKUP(E78,'ACTIVOS CODIGO'!E:F,2,0) -> ACTIVO DISPONIBLE | G78: 110 | H78: =VLOOKUP(G78,'PUB 21'!$A$1:$B$29,2,0) -> FONDOS DEL SITUADO COORDINADO | M78: =CONCATENATE(TEXT(A78,"0"),"-",TEXT(C78,"0"),"-",TEXT(E78,"0"),"-",TEXT(LEFT(G78,2),"00"),"-",TEXT(RIGHT(G78,1),"0"),TEXT(I78,"0"),"-",TEXT(K78,"00")) -> 1-1-1-11-00-00 | N78: =IF(L78="",IF(J78="",IF(H78="",IF(F78="",IF(D78="",B78,D78),F78),H78),J78),L78) -> FONDOS DEL SITUADO COORDINADO | O78: =IF(P78="",0,IF(M77=M78,IF(O77="",0,O77)+1,"")) -> 1 | P78: I.M.C.P. 0601-0001-27-0014072037 | Q78: =CONCATENATE(TEXT(A78,"0"),"-",TEXT(C78,"0"),"-",TEXT(E78,"0"),"-",TEXT(LEFT(G78,2),"00"),"-",TEXT(RIGHT(G78,1),"0"),TEXT(I78,"0"),"-",TEXT(K78,"00"),"-",TEXT(O78,"000")) -> 1-1-1-11-00-00-001 | R78: =IF(P78="",IF(L78="",IF(J78="",IF(H78="",IF(F78="",IF(D78="",B78,D78),F78),H78),J78),L78),P78) -> I.M.C.P. 0601-0001-27-0014072037
A79: 1 | B79: =VLOOKUP(A79,'ACTIVOS CODIGO'!A:B,2,0) -> ACTIVO | C79: 1 | D79: =VLOOKUP(C79,'ACTIVOS CODIGO'!C:D,2,0) -> ACTIVO DEL TESORO = ACTIVO CORRIENTE | E79: 1 | F79: =VLOOKUP(E79,'ACTIVOS CODIGO'!E:F,2,0) -> ACTIVO DISPONIBLE | G79: 110 | H79: =VLOOKUP(G79,'PUB 21'!$A$1:$B$29,2,0) -> FONDOS DEL SITUADO COORDINADO | M79: =CONCATENATE(TEXT(A79,"0"),"-",TEXT(C79,"0"),"-",TEXT(E79,"0"),"-",TEXT(LEFT(G79,2),"00"),"-",TEXT(RIGHT(G79,1),"0"),TEXT(I79,"0"),"-",TEXT(K79,"00")) -> 1-1-1-11-00-00 | N79: =IF(L79="",IF(J79="",IF(H79="",IF(F79="",IF(D79="",B79,D79),F79),H79),J79),L79) -> FONDOS DEL SITUADO COORDINADO | O79: =IF(P79="",0,IF(M78=M79,IF(O78="",0,O78)+1,"")) -> 2 | P79: I.M.C.P. 004103477 SITUADO MUNICIPAL 2021 | Q79: =CONCATENATE(TEXT(A79,"0"),"-",TEXT(C79,"0"),"-",TEXT(E79,"0"),"-",TEXT(LEFT(G79,2),"00"),"-",TEXT(RIGHT(G79,1),"0"),TEXT(I79,"0"),"-",TEXT(K79,"00"),"-",TEXT(O79,"000")) -> 1-1-1-11-00-00-002 | R79: =IF(P79="",IF(L79="",IF(J79="",IF(H79="",IF(F79="",IF(D79="",B79,D79),F79),H79),J79),L79),P79) -> I.M.C.P. 004103477 SITUADO MUNICIPAL 2021
A80: 1 | B80: =VLOOKUP(A80,'ACTIVOS CODIGO'!A:B,2,0) -> ACTIVO | C80: 1 | D80: =VLOOKUP(C80,'ACTIVOS CODIGO'!C:D,2,0) -> ACTIVO DEL TESORO = ACTIVO CORRIENTE | E80: 1 | F80: =VLOOKUP(E80,'ACTIVOS CODIGO'!E:F,2,0) -> ACTIVO DISPONIBLE | G80: 110 | H80: =VLOOKUP(G80,'PUB 21'!$A$1:$B$29,2,0) -> FONDOS DEL SITUADO COORDINADO | M80: =CONCATENATE(TEXT(A80,"0"),"-",TEXT(C80,"0"),"-",TEXT(E80,"0"),"-",TEXT(LEFT(G80,2),"00"),"-",TEXT(RIGHT(G80,1),"0"),TEXT(I80,"0"),"-",TEXT(K80,"00")) -> 1-1-1-11-00-00 | N80: =IF(L80="",IF(J80="",IF(H80="",IF(F80="",IF(D80="",B80,D80),F80),H80),J80),L80) -> FONDOS DEL SITUADO COORDINADO | O80: =IF(P80="",0,IF(M79=M80,IF(O79="",0,O79)+1,"")) -> 3 | P80: I.M.C.P. 0601-0001-21-0014107205 "A.M.L. SITUADO MCPAL. 2022" | Q80: =CONCATENATE(TEXT(A80,"0"),"-",TEXT(C80,"0"),"-",TEXT(E80,"0"),"-",TEXT(LEFT(G80,2),"00"),"-",TEXT(RIGHT(G80,1),"0"),TEXT(I80,"0"),"-",TEXT(K80,"00"),"-",TEXT(O80,"000")) -> 1-1-1-11-00-00-003 | R80: =IF(P80="",IF(L80="",IF(J80="",IF(H80="",IF(F80="",IF(D80="",B80,D80),F80),H80),J80),L80),P80) -> I.M.C.P. 0601-0001-21-0014107205 "A.M.L. SITUADO MCPAL. 2022"
A81: 1 | B81: =VLOOKUP(A81,'ACTIVOS CODIGO'!A:B,2,0) -> ACTIVO | C81: 1 | D81: =VLOOKUP(C81,'ACTIVOS CODIGO'!C:D,2,0) -> ACTIVO DEL TESORO = ACTIVO CORRIENTE | E81: 1 | F81: =VLOOKUP(E81,'ACTIVOS CODIGO'!E:F,2,0) -> ACTIVO DISPONIBLE | G81: 110 | H81: =VLOOKUP(G81,'PUB 21'!$A$1:$B$29,2,0) -> FONDOS DEL SITUADO COORDINADO | M81: =CONCATENATE(TEXT(A81,"0"),"-",TEXT(C81,"0"),"-",TEXT(E81,"0"),"-",TEXT(LEFT(G81,2),"00"),"-",TEXT(RIGHT(G81,1),"0"),TEXT(I81,"0"),"-",TEXT(K81,"00")) -> 1-1-1-11-00-00 | N81: =IF(L81="",IF(J81="",IF(H81="",IF(F81="",IF(D81="",B81,D81),F81),H81),J81),L81) -> FONDOS DEL SITUADO COORDINADO | O81: =IF(P81="",0,IF(M80=M81,IF(O80="",0,O80)+1,"")) -> 4 | P81: VENEZUELA 0102-0792-23-0000078524 "A.M.L. SITUADO MCPAL. 2022" | Q81: =CONCATENATE(TEXT(A81,"0"),"-",TEXT(C81,"0"),"-",TEXT(E81,"0"),"-",TEXT(LEFT(G81,2),"00"),"-",TEXT(RIGHT(G81,1),"0"),TEXT(I81,"0"),"-",TEXT(K81,"00"),"-",TEXT(O81,"000")) -> 1-1-1-11-00-00-004 | R81: =IF(P81="",IF(L81="",IF(J81="",IF(H81="",IF(F81="",IF(D81="",B81,D81),F81),H81),J81),L81),P81) -> VENEZUELA 0102-0792-23-0000078524 "A.M.L. SITUADO MCPAL. 2022"
...

Sheet PUB 21
A1: 102 | B1: TESORERIA MUNICIPAL
A2: 110 | B2: FONDOS DEL SITUADO COORDINADO
A3: 120 | B3: DOCUMENTOS NEGOCIABLES
A4: 122 | B4: INGRESOS POR RECAUDAR
A5: 126 | B5: FONDOS EN AVANCE
A6: 128 | B6: FONDOS ANTICIPADOS
A7: 130 | B7: FONDOS ESPECIALES
A8: 132 | B8: FONDOS DE TERCEROS
A9: 200 | B9: SITUACION FISCAL DEL TESORO
A10: 210 | B10: APORTE DE CAPITAL Y ACCIONES
A11: 212 | B11: BIENES INMUEBLES
A12: 214 | B12: BIENES MUEBLES
... A29: 401 | B29: FONDOS BANCOS INTERVENIDOS

Sheet ACTIVOS CODIGO
A1: 1 | B1: ACTIVO | C1: 1 | D1: ACTIVO DEL TESORO = ACTIVO CORRIENTE | E1: 1 | F1: ACTIVO DISPONIBLE | H1: 1 | I1: PASIVO DEL TESORO = PASIVO CORRIENTE | J1: 1 | K1: PASIVO DISPONIBLE
A2: 2 | B2: PASIVO | C2: 2 | D2: ACTIVO DE LA HACIENDA = ACTIVO NO CORRIENTE | E2: 2 | F2: ACTIVO EXIGIBLE | H2: 2 | I2: PASIVO DE LA HACIENDA = PASIVO NO CORRIENTE | J2: 2 | K2: PASIVO EXIGIBLE
A3: 3 | B3: INGRESOS | C3: 3 | D3: INGRESO DE LA HACIENDA
A4: 4 | B4: GASTOS | C4: 4 | D4: CUENTA DE GASTO HACIENDA
A5: 5 | B5: LIQUIDACION DEL PRESUPUESTO | C5: 5 | D5: CUENTA DE RESULTADOS DE LA HACIENDA
A6: 6 | B6: CUENTA DE ORDEN | C6: 6 | D6: BANCO INTERVERNIDO DE LA HACIENDA
C7: 7 | D7: CUENTA DE ORDEN DE LA HACIENDA
